Workbook

Sheet MODE D'EMPLOI
B1: RIJAL FIT — EN ROUTE VERS LE RAMADAN
B2: TON CORPS AU SERVICE DE TA FOI
B5: BIENVENUE : TON PARCOURS DE 24 SEMAINES VERS LE RAMADAN
B6: • | C6: Cet outil t'accompagne pendant 24 semaines (environ 6 mois) pour installer, semaine après semaine, des habitudes régulières pour ta foi et pour ton corps, afin d'arriver au Ramadan prêt. Il mesure ta régularité, jamais ta sincérité ni ta valeur auprès d'Allah.
B8: CE QUE CONTIENT CE FICHIER
B9: • | C9: MON SUIVI QUOTIDIEN : c'est là que tu remplis ta journée (tes missions, ton eau, tes repas, ton sommeil, ton sport). 2 minutes chaque soir.
B10: • | C10: MON BILAN RIJAL FIT : ton score, ton radar et ton analyse de la semaine, calculés automatiquement.
B11: • | C11: MA PROGRESSION : ta courbe sur 24 semaines.
B12: • | C12: MES MISSIONS : les 30 missions du programme, avec comment les faire, le hadith et la récompense de chacune.
B13: • | C13: VERSETS : 10 versets par semaine, avec leur traduction. Ta semaine en cours est surlignée.
B14: • | C14: MISSIONS : l'espace du coach, pour modifier ou ajouter des missions.
B16: COMMENT SE DÉROULE LE PROGRAMME
B17: 1 | C17: Semaine 1 : une nouvelle mission chaque jour (J1 à J7). Tu installes 7 habitudes en 7 jours et tu les gardes toutes.
B18: 2 | C18: Semaines 2 à 24 : une seule nouvelle mission par semaine, le premier jour de la semaine. Elle apparaît seule dans ton suivi. À la fin, tu tiens 30 habitudes.
B19: 3 | C19: Chaque semaine : 10 versets à lire, relire et méditer dans l'onglet VERSETS.
B20: 4 | C20: Tu avances à ton rythme : si une semaine est difficile, garde simplement tes habitudes sans te juger. Mieux vaut peu et régulier que beaucoup et abandonné.
B22: AU DÉMARRAGE (une seule fois, 5 minutes)
B23: 1 | C23: Onglet MON SUIVI QUOTIDIEN : écris ton nom, la date de ton premier jour (Jour 1) et la date de début de ta semaine. Pour la semaine 1, c'est la même date que le Jour 1. Pour la semaine 2, tu ajoutes 7 jours, et ainsi de suite.
B24: 2 | C24: Règle tes objectifs chiffrés (eau, repas, sommeil, coucher, activité) selon tes capacités. Ils ne sont pas les mêmes pour tout le monde, et c'est normal.
B25: 3 | C25: Ouvre MES MISSIONS pour voir le programme complet, et VERSETS pour lire les versets de ta première semaine.
B27: CHAQUE SOIR (2 minutes)
B28: 1 | C28: Dans MON SUIVI QUOTIDIEN, remplis uniquement les cellules ivoire à bordure dorée : liste déroulante (Fait / Pas fait / N/A, Oui / Non) et petits nombres.
B29: 2 | C29: Pour chaque mission du jour, choisis Fait, Pas fait ou N/A. Une mission qui ne concerne pas ce jour-là (jeûne du lundi ou du jeudi, prière de nuit, prière en groupe en voyage, maladie…) se marque N/A : elle n'est pas comptée contre toi.
B30: 3 | C30: Relis un ou deux versets de ta semaine avant de dormir.
B32: CHAQUE FIN DE SEMAINE (5 minutes)
B33: 1 | C33: Ouvre MON BILAN RIJAL FIT : score, analyse, et mission de la semaine suivante s'affichent automatiquement.
B34: 2 | C34: Recopie la ligne « À reporter » du bilan dans MA PROGRESSION, sur la ligne de ta semaine (Collage spécial › Valeurs), et écris ce que tu retiens.
B35: 3 | C35: Prépare la semaine suivante : enregistre une copie du fichier (ex. « Rijal Fit - Semaine 3 »), vide la saisie (Excel ordinateur : clique dans la zone Nom, en haut à gauche au-dessus de la colonne A, tape SAISIES_SEMAINE, Entrée, puis touche Suppr), puis ajoute 7 jours à la date de début de semaine. La nouvelle mission apparaît toute seule.
B37: LES RÈGLES DU JEU
B38: • | C38: Case vide = donnée manquante, jamais un échec. Elle n'est pas comptée.
B39: • | C39: N/A = non applicable (voyage, maladie, jour sans objet). Pas de pénalité.
B40: • | C40: Case grisée dans la partie Religion = mission pas encore introduite ce jour-là. Elle n'est pas comptée.
B41: • | C41: Les missions s'ajoutent automatiquement dès leur jour d'introduction et restent ensuite : tu conserves les habitudes précédentes.
B42: • | C42: Bilan complet : il faut un nombre minimum de jours renseignés dans chaque pilier (réglé par le coach, 4 jours sur 7 par défaut). Sinon le bilan est « incomplet » et le score global ne s'affiche pas.
B44: LA MÉTHODE 5-2-2-1
B45: • | C45: Score global /100 = Religion × 0,50 + Nutrition × 0,20 + Sommeil × 0,20 + Sport × 0,10. Ces coefficients sont pédagogiques et propres à la méthode Rijal Fit : ils ne classent pas la valeur religieuse des actes.
B46: • | C46: Religion : missions faites / missions actives renseignées. Obligations et habitudes recommandées sont affichées séparément dans le détail du bilan.
B47: • | C47: Nutrition : moyenne de l'hydratation (vs ton objectif), des repas équilibrés (vs ton objectif) et de la régularité des horaires de repas.
B48: • | C48: Sommeil : moyenne de la durée (vs ton objectif), d'un coucher dans ta plage horaire et de ta routine de récupération.
B49: • | C49: Sport : moyenne des minutes (vs ton objectif), des séances prévues réalisées et de la régularité de la semaine (jours actifs vs ton objectif).
...

Sheet MON SUIVI QUOTIDIEN
B1: RIJAL FIT — EN ROUTE VERS LE RAMADAN
B2: TON CORPS AU SERVICE DE TA FOI
B3: Aller à → | E3: Religion | F3: Nutrition | G3: Sommeil | H3: Sport | I3: Notes | K3: Mon bilan ›
B4: Saisis uniquement dans les cellules ivoire à bordure dorée. Tout le reste se calcule seul. Une case vide = donnée manquante, jamais un échec.
B5: MES INFORMATIONS
B6: Nom du participant | H6: N° de semaine du challenge | K6: =IF(OR(C7="",C8=""),"",INT((C8-C7)/7)+1)
B7: Date de début du challenge (Jour 1) | H7: Jours du challenge couverts | K7: =IF(E22="","",IF(K22<1,"avant le début",IF(E22<1,"J1",CONCATENATE("J",E22)) & " à J" & K22))
B8: Date de début de semaine | H8: Missions actives cette semaine | K8: =COUNTIF(B28:B67,"?*") -> 0
B9: Mes objectifs personnels de la semaine
B11: MES OBJECTIFS CHIFFRÉS — à adapter à TES capacités (avec ton coach si besoin)
B12: Hydratation visée par jour (litres) | C12: 2 | E12: Exemple : 1,5 à 2,5 L selon ton gabarit, ton activité et la saison.
B13: Repas équilibrés visés par jour | C13: 2 | E13: Protéines + légumes + féculents de qualité. Pas de calories imposées.
B14: Sommeil visé par nuit (heures) | C14: 7.5 | E14: Saisie en heures décimales : 7,5 = 7 h 30.
B15: Heure de coucher visée | C15: 0.95833333 | E15: Saisie au format 23:00. Sert à mesurer la régularité de tes horaires.
B16: Tolérance autour de l'heure de coucher (minutes) | C16: 30 | E16: Coucher compté « dans la plage » s'il est à ± cette marge de l'heure visée.
B17: Minutes d'activité visées par jour actif | C17: 20 | E17: Marche, renforcement, sport… À adapter à ta condition physique.
B18: Jours actifs visés par semaine | C18: 3 | E18: Nombre de jours avec au moins un peu d'activité physique.
B20: MA SEMAINE
B21: Date | E21: =IF($C$8="","",$C$8+0) | F21: =IF($C$8="","",$C$8+1) | G21: =IF($C$8="","",$C$8+2) | H21: =IF($C$8="","",$C$8+3) | I21: =IF($C$8="","",$C$8+4) | J21: =IF($C$8="","",$C$8+5) | K21: =IF($C$8="","",$C$8+6)
B22: Jour du challenge | E22: =IF(OR($C$7="",$C$8=""),"",E21-$C$7+1) | F22: =IF(OR($C$7="",$C$8=""),"",F21-$C$7+1) | G22: =IF(OR($C$7="",$C$8=""),"",G21-$C$7+1) | H22: =IF(OR($C$7="",$C$8=""),"",H21-$C$7+1) | I22: =IF(OR($C$7="",$C$8=""),"",I21-$C$7+1) | J22: =IF(OR($C$7="",$C$8=""),"",J21-$C$7+1) | K22: =IF(OR($C$7="",$C$8=""),"",K21-$C$7+1)
B24: A. RELIGION ET HABITUDES SPIRITUELLES — 50 %
B25: Mission | C25: Dès | D25: Nature | E25: =IF(E$21="","Lun",CHOOSE(WEEKDAY(E$21,2),"Lun","Mar","Mer","Jeu","Ven","Sam","Dim")&" "&RIGHT("0"&DAY(E$21),2)&"/"&RIGHT("0"&MONTH(E$21),2)) -> Lun | F25: =IF(F$21="","Mar",CHOOSE(WEEKDAY(F$21,2),"Lun","Mar","Mer","Jeu","Ven","Sam","Dim")&" "&RIGHT("0"&DAY(F$21),2)&"/"&RIGHT("0"&MONTH(F$21),2)) -> Mar | G25: =IF(G$21="","Mer",CHOOSE(WEEKDAY(G$21,2),"Lun","Mar","Mer","Jeu","Ven","Sam","Dim")&" "&RIGHT("0"&DAY(G$21),2)&"/"&RIGHT("0"&MONTH(G$21),2)) -> Mer | H25: =IF(H$21="","Jeu",CHOOSE(WEEKDAY(H$21,2),"Lun","Mar","Mer","Jeu","Ven","Sam","Dim")&" "&RIGHT("0"&DAY(H$21),2)&"/"&RIGHT("0"&MONTH(H$21),2)) -> Jeu | I25: =IF(I$21="","Ven",CHOOSE(WEEKDAY(I$21,2),"Lun","Mar","Mer","Jeu","Ven","Sam","Dim")&" "&RIGHT("0"&DAY(I$21),2)&"/"&RIGHT("0"&MONTH(I$21),2)) -> Ven | J25: =IF(J$21="","Sam",CHOOSE(WEEKDAY(J$21,2),"Lun","Mar","Mer","Jeu","Ven","Sam","Dim")&" "&RIGHT("0"&DAY(J$21),2)&"/"&RIGHT("0"&MONTH(J$21),2)) -> Sam | K25: =IF(K$21="","Dim",CHOOSE(WEEKDAY(K$21,2),"Lun","Mar","Mer","Jeu","Ven","Sam","Dim")&" "&RIGHT("0"&DAY(K$21),2)&"/"&RIGHT("0"&MONTH(K$21),2)) -> Dim | L25: Régularité
B26: Choisis Fait / Pas fait / N/A. Case grisée = mission pas encore introduite ce jour-là : elle n'est pas comptée. N/A (voyage, maladie, contexte particulier) n'est pas pénalisé.
B27: Les missions apparaissent automatiquement dès leur jour d'introduction et restent ensuite. Elles se gèrent dans l'onglet MISSIONS.
B28: =IF(OR(MISSIONS!$D8="",MISSIONS!$C8="",$K$22=""),"",IF(MISSIONS!$C8<=$K$22,MISSIONS!$D8,"")) | C28: =IF(B28="","",MISSIONS!$C8) | D28: =IF(B28="","",IF(MISSIONS!$E8="Obligation","Oblig.","Recom.")) | L28: =IF(B28="","",IF(SUMPRODUCT((E28:K28="Fait")*($E$22:$K$22>=$C28))+SUMPRODUCT((E28:K28="Pas fait")*($E$22:$K$22>=$C28))=0,"",SUMPRODUCT((E28:K28="Fait")*($E$22:$K$22>=$C28))/(SUMPRODUCT((E28:K28="Fait")*($E$22:$K$22>=$C28))+SUMPRODUCT((E28:K28="Pas fait")*($E$22:$K$22>=$C28)))))
B29: =IF(OR(MISSIONS!$D9="",MISSIONS!$C9="",$K$22=""),"",IF(MISSIONS!$C9<=$K$22,MISSIONS!$D9,"")) | C29: =IF(B29="","",MISSIONS!$C9) | D29: =IF(B29="","",IF(MISSIONS!$E9="Obligation","Oblig.","Recom.")) | L29: =IF(B29="","",IF(SUMPRODUCT((E29:K29="Fait")*($E$22:$K$22>=$C29))+SUMPRODUCT((E29:K29="Pas fait")*($E$22:$K$22>=$C29))=0,"",SUMPRODUCT((E29:K29="Fait")*($E$22:$K$22>=$C29))/(SUMPRODUCT((E29:K29="Fait")*($E$22:$K$22>=$C29))+SUMPRODUCT((E29:K29="Pas fait")*($E$22:$K$22>=$C29)))))
B30: =IF(OR(MISSIONS!$D10="",MISSIONS!$C10="",$K$22=""),"",IF(MISSIONS!$C10<=$K$22,MISSIONS!$D10,"")) | C30: =IF(B30="","",MISSIONS!$C10) | D30: =IF(B30="","",IF(MISSIONS!$E10="Obligation","Oblig.","Recom.")) | L30: =IF(B30="","",IF(SUMPRODUCT((E30:K30="Fait")*($E$22:$K$22>=$C30))+SUMPRODUCT((E30:K30="Pas fait")*($E$22:$K$22>=$C30))=0,"",SUMPRODUCT((E30:K30="Fait")*($E$22:$K$22>=$C30))/(SUMPRODUCT((E30:K30="Fait")*($E$22:$K$22>=$C30))+SUMPRODUCT((E30:K30="Pas fait")*($E$22:$K$22>=$C30)))))
B31: =IF(OR(MISSIONS!$D11="",MISSIONS!$C11="",$K$22=""),"",IF(MISSIONS!$C11<=$K$22,MISSIONS!$D11,"")) | C31: =IF(B31="","",MISSIONS!$C11) | D31: =IF(B31="","",IF(MISSIONS!$E11="Obligation","Oblig.","Recom.")) | L31: =IF(B31="","",IF(SUMPRODUCT((E31:K31="Fait")*($E$22:$K$22>=$C31))+SUMPRODUCT((E31:K31="Pas fait")*($E$22:$K$22>=$C31))=0,"",SUMPRODUCT((E31:K31="Fait")*($E$22:$K$22>=$C31))/(SUMPRODUCT((E31:K31="Fait")*($E$22:$K$22>=$C31))+SUMPRODUCT((E31:K31="Pas fait")*($E$22:$K$22>=$C31)))))
B32: =IF(OR(MISSIONS!$D12="",MISSIONS!$C12="",$K$22=""),"",IF(MISSIONS!$C12<=$K$22,MISSIONS!$D12,"")) | C32: =IF(B32="","",MISSIONS!$C12) | D32: =IF(B32="","",IF(MISSIONS!$E12="Obligation","Oblig.","Recom.")) | L32: =IF(B32="","",IF(SUMPRODUCT((E32:K32="Fait")*($E$22:$K$22>=$C32))+SUMPRODUCT((E32:K32="Pas fait")*($E$22:$K$22>=$C32))=0,"",SUMPRODUCT((E32:K32="Fait")*($E$22:$K$22>=$C32))/(SUMPRODUCT((E32:K32="Fait")*($E$22:$K$22>=$C32))+SUMPRODUCT((E32:K32="Pas fait")*($E$22:$K$22>=$C32)))))
B33: =IF(OR(MISSIONS!$D13="",MISSIONS!$C13="",$K$22=""),"",IF(MISSIONS!$C13<=$K$22,MISSIONS!$D13,"")) | C33: =IF(B33="","",MISSIONS!$C13) | D33: =IF(B33="","",IF(MISSIONS!$E13="Obligation","Oblig.","Recom.")) | L33: =IF(B33="","",IF(SUMPRODUCT((E33:K33="Fait")*($E$22:$K$22>=$C33))+SUMPRODUCT((E33:K33="Pas fait")*($E$22:$K$22>=$C33))=0,"",SUMPRODUCT((E33:K33="Fait")*($E$22:$K$22>=$C33))/(SUMPRODUCT((E33:K33="Fait")*($E$22:$K$22>=$C33))+SUMPRODUCT((E33:K33="Pas fait")*($E$22:$K$22>=$C33)))))
B34: =IF(OR(MISSIONS!$D14="",MISSIONS!$C14="",$K$22=""),"",IF(MISSIONS!$C14<=$K$22,MISSIONS!$D14,"")) | C34: =IF(B34="","",MISSIONS!$C14) | D34: =IF(B34="","",IF(MISSIONS!$E14="Obligation","Oblig.","Recom.")) | L34: =IF(B34="","",IF(SUMPRODUCT((E34:K34="Fait")*($E$22:$K$22>=$C34))+SUMPRODUCT((E34:K34="Pas fait")*($E$22:$K$22>=$C34))=0,"",SUMPRODUCT((E34:K34="Fait")*($E$22:$K$22>=$C34))/(SUMPRODUCT((E34:K34="Fait")*($E$22:$K$22>=$C34))+SUMPRODUCT((E34:K34="Pas fait")*($E$22:$K$22>=$C34)))))
B35: =IF(OR(MISSIONS!$D15="",MISSIONS!$C15="",$K$22=""),"",IF(MISSIONS!$C15<=$K$22,MISSIONS!$D15,"")) | C35: =IF(B35="","",MISSIONS!$C15) | D35: =IF(B35="","",IF(MISSIONS!$E15="Obligation","Oblig.","Recom.")) | L35: =IF(B35="","",IF(SUMPRODUCT((E35:K35="Fait")*($E$22:$K$22>=$C35))+SUMPRODUCT((E35:K35="Pas fait")*($E$22:$K$22>=$C35))=0,"",SUMPRODUCT((E35:K35="Fait")*($E$22:$K$22>=$C35))/(SUMPRODUCT((E35:K35="Fait")*($E$22:$K$22>=$C35))+SUMPRODUCT((E35:K35="Pas fait")*($E$22:$K$22>=$C35)))))
B36: =IF(OR(MISSIONS!$D16="",MISSIONS!$C16="",$K$22=""),"",IF(MISSIONS!$C16<=$K$22,MISSIONS!$D16,"")) | C36: =IF(B36="","",MISSIONS!$C16) | D36: =IF(B36="","",IF(MISSIONS!$E16="Obligation","Oblig.","Recom.")) | L36: =IF(B36="","",IF(SUMPRODUCT((E36:K36="Fait")*($E$22:$K$22>=$C36))+SUMPRODUCT((E36:K36="Pas fait")*($E$22:$K$22>=$C36))=0,"",SUMPRODUCT((E36:K36="Fait")*($E$22:$K$22>=$C36))/(SUMPRODUCT((E36:K36="Fait")*($E$22:$K$22>=$C36))+SUMPRODUCT((E36:K36="Pas fait")*($E$22:$K$22>=$C36)))))
B37: =IF(OR(MISSIONS!$D17="",MISSIONS!$C17="",$K$22=""),"",IF(MISSIONS!$C17<=$K$22,MISSIONS!$D17,"")) | C37: =IF(B37="","",MISSIONS!$C17) | D37: =IF(B37="","",IF(MISSIONS!$E17="Obligation","Oblig.","Recom.")) | L37: =IF(B37="","",IF(SUMPRODUCT((E37:K37="Fait")*($E$22:$K$22>=$C37))+SUMPRODUCT((E37:K37="Pas fait")*($E$22:$K$22>=$C37))=0,"",SUMPRODUCT((E37:K37="Fait")*($E$22:$K$22>=$C37))/(SUMPRODUCT((E37:K37="Fait")*($E$22:$K$22>=$C37))+SUMPRODUCT((E37:K37="Pas fait")*($E$22:$K$22>=$C37)))))
B38: =IF(OR(MISSIONS!$D18="",MISSIONS!$C18="",$K$22=""),"",IF(MISSIONS!$C18<=$K$22,MISSIONS!$D18,"")) | C38: =IF(B38="","",MISSIONS!$C18) | D38: =IF(B38="","",IF(MISSIONS!$E18="Obligation","Oblig.","Recom.")) | L38: =IF(B38="","",IF(SUMPRODUCT((E38:K38="Fait")*($E$22:$K$22>=$C38))+SUMPRODUCT((E38:K38="Pas fait")*($E$22:$K$22>=$C38))=0,"",SUMPRODUCT((E38:K38="Fait")*($E$22:$K$22>=$C38))/(SUMPRODUCT((E38:K38="Fait")*($E$22:$K$22>=$C38))+SUMPRODUCT((E38:K38="Pas fait")*($E$22:$K$22>=$C38)))))
B39: =IF(OR(MISSIONS!$D19="",MISSIONS!$C19="",$K$22=""),"",IF(MISSIONS!$C19<=$K$22,MISSIONS!$D19,"")) | C39: =IF(B39="","",MISSIONS!$C19) | D39: =IF(B39="","",IF(MISSIONS!$E19="Obligation","Oblig.","Recom.")) | L39: =IF(B39="","",IF(SUMPRODUCT((E39:K39="Fait")*($E$22:$K$22>=$C39))+SUMPRODUCT((E39:K39="Pas fait")*($E$22:$K$22>=$C39))=0,"",SUMPRODUCT((E39:K39="Fait")*($E$22:$K$22>=$C39))/(SUMPRODUCT((E39:K39="Fait")*($E$22:$K$22>=$C39))+SUMPRODUCT((E39:K39="Pas fait")*($E$22:$K$22>=$C39)))))
... B67: =IF(OR(MISSIONS!$D47="",MISSIONS!$C47="",$K$22=""),"",IF(MISSIONS!$C47<=$K$22,MISSIONS!$D47,"")) | C67: =IF(B67="","",MISSIONS!$C47) | D67: =IF(B67="","",IF(MISSIONS!$E47="Obligation","Oblig.","Recom.")) | L67: =IF(B67="","",IF(SUMPRODUCT((E67:K67="Fait")*($E$22:$K$22>=$C67))+SUMPRODUCT((E67:K67="Pas fait")*($E$22:$K$22>=$C67))=0,"",SUMPRODUCT((E67:K67="Fait")*($E$22:$K$22>=$C67))/(SUMPRODUCT((E67:K67="Fait")*($E$22:$K$22>=$C67))+SUMPRODUCT((E67:K67="Pas fait")*($E$22:$K$22>=$C67)))))
B68: Taux de réalisation Religion | E68: =IF(CALCULS!E7="","",CALCULS!E7) | F68: =IF(CALCULS!F7="","",CALCULS!F7) | G68: =IF(CALCULS!G7="","",CALCULS!G7) | H68: =IF(CALCULS!H7="","",CALCULS!H7) | I68: =IF(CALCULS!I7="","",CALCULS!I7) | J68: =IF(CALCULS!J7="","",CALCULS!J7) | K68: =IF(CALCULS!K7="","",CALCULS!K7) | L68: =IF(CALCULS!L7="","—",CALCULS!L7) -> —
B70: B. NUTRITION — 20 %
B71: Indicateur | C71: Objectif | E71: =IF(E$21="","Lun",CHOOSE(WEEKDAY(E$21,2),"Lun","Mar","Mer","Jeu","Ven","Sam","Dim")&" "&RIGHT("0"&DAY(E$21),2)&"/"&RIGHT("0"&MONTH(E$21),2)) -> Lun | F71: =IF(F$21="","Mar",CHOOSE(WEEKDAY(F$21,2),"Lun","Mar","Mer","Jeu","Ven","Sam","Dim")&" "&RIGHT("0"&DAY(F$21),2)&"/"&RIGHT("0"&MONTH(F$21),2)) -> Mar | G71: =IF(G$21="","Mer",CHOOSE(WEEKDAY(G$21,2),"Lun","Mar","Mer","Jeu","Ven","Sam","Dim")&" "&RIGHT("0"&DAY(G$21),2)&"/"&RIGHT("0"&MONTH(G$21),2)) -> Mer | H71: =IF(H$21="","Jeu",CHOOSE(WEEKDAY(H$21,2),"Lun","Mar","Mer","Jeu","Ven","Sam","Dim")&" "&RIGHT("0"&DAY(H$21),2)&"/"&RIGHT("0"&MONTH(H$21),2)) -> Jeu | I71: =IF(I$21="","Ven",CHOOSE(WEEKDAY(I$21,2),"Lun","Mar","Mer","Jeu","Ven","Sam","Dim")&" "&RIGHT("0"&DAY(I$21),2)&"/"&RIGHT("0"&MONTH(I$21),2)) -> Ven | J71: =IF(J$21="","Sam",CHOOSE(WEEKDAY(J$21,2),"Lun","Mar","Mer","Jeu","Ven","Sam","Dim")&" "&RIGHT("0"&DAY(J$21),2)&"/"&RIGHT("0"&MONTH(J$21),2)) -> Sam | K71: =IF(K$21="","Dim",CHOOSE(WEEKDAY(K$21,2),"Lun","Mar","Mer","Jeu","Ven","Sam","Dim")&" "&RIGHT("0"&DAY(K$21),2)&"/"&RIGHT("0"&MONTH(K$21),2)) -> Dim | L71: Taux semaine
...

Sheet MON BILAN RIJAL FIT
B1: RIJAL FIT — EN ROUTE VERS LE RAMADAN
B2: TON CORPS AU SERVICE DE TA FOI
L3: ‹ Mon suivi
B4: =IF('MON SUIVI QUOTIDIEN'!C6="","Participant : à renseigner",'MON SUIVI QUOTIDIEN'!C6)&IF('MON SUIVI QUOTIDIEN'!K6="",""," · Semaine "&'MON SUIVI QUOTIDIEN'!K6&" du challenge")&IF('MON SUIVI QUOTIDIEN'!E21="",""," · du "&RIGHT("0"&DAY('MON SUIVI QUOTIDIEN'!E21),2)&"/"&RIGHT("0"&MONTH('MON SUIVI QUOTIDIEN'!E21),2)&" au "&RIGHT("0"&DAY('MON SUIVI QUOTIDIEN'!K21),2)&"/"&RIGHT("0"&MONTH('MON SUIVI QUOTIDIEN'!K21),2)) -> Participant : à renseigner
B6: MON SCORE GLOBAL — MÉTHODE 5-2-2-1
B7: =IF(CALCULS!$C$35=1,CALCULS!$C$36,"—") -> — | E7: =IF(CALCULS!$C$35=1,"✔ Bilan complet. Score calculé avec la méthode 5-2-2-1 : Religion × 0,50 + Nutrition × 0,20 + Sommeil × 0,20 + Sport × 0,10.",IF(CALCULS!$C$37=0,"Aucune donnée saisie pour cette semaine. Remplis ton suivi quotidien pour voir ton bilan.","⚠ Bilan incomplet : il faut au moins "&MISSIONS!$E$4&" jours renseignés pour : "&CALCULS!$C$39&". Le score global s'affichera dès que ce sera le cas. Les cases vides ne sont pas comptées comme des échecs.")) -> Aucune donnée saisie pour cette semaine. Remplis ton suivi quotidien pour voir ton bilan.
E9: Ce score mesure la régularité de tes habitudes. Il ne mesure jamais ta sincérité, ta piété ni ta valeur auprès d'Allah, et ne sert à aucun classement.
B12: MES 4 PILIERS
B13: Pilier | C13: Taux de réalisation | E13: Coef. | F13: Points | G13: Jours renseignés | I13: Statut
B14: =CALCULS!B30 -> Religion | C14: =IF(CALCULS!C30="","—",CALCULS!C30) -> — | E14: =CALCULS!F30 -> 0.5 | F14: =IF(CALCULS!E30<>"Complet","—",ROUND(CALCULS!C30*CALCULS!F30*100,1)) -> — | G14: =CALCULS!D30&" / 7" -> 0 / 7 | I14: =CALCULS!E30 -> Aucune donnée
B15: =CALCULS!B31 -> Nutrition | C15: =IF(CALCULS!C31="","—",CALCULS!C31) -> — | E15: =CALCULS!F31 -> 0.2 | F15: =IF(CALCULS!E31<>"Complet","—",ROUND(CALCULS!C31*CALCULS!F31*100,1)) -> — | G15: =CALCULS!D31&" / 7" -> 0 / 7 | I15: =CALCULS!E31 -> Aucune donnée
B16: =CALCULS!B32 -> Sommeil | C16: =IF(CALCULS!C32="","—",CALCULS!C32) -> — | E16: =CALCULS!F32 -> 0.2 | F16: =IF(CALCULS!E32<>"Complet","—",ROUND(CALCULS!C32*CALCULS!F32*100,1)) -> — | G16: =CALCULS!D32&" / 7" -> 0 / 7 | I16: =CALCULS!E32 -> Aucune donnée
B17: =CALCULS!B33 -> Sport | C17: =IF(CALCULS!C33="","—",CALCULS!C33) -> — | E17: =CALCULS!F33 -> 0.1 | F17: =IF(CALCULS!E33<>"Complet","—",ROUND(CALCULS!C33*CALCULS!F33*100,1)) -> — | G17: =CALCULS!D33&" / 7" -> 0 / 7 | I17: =CALCULS!E33 -> Aucune donnée
B18: Le radar ci-dessous montre les taux de réalisation bruts (non pondérés). Le score global applique les coefficients pédagogiques 5-2-2-1, qui ne sont pas une hiérarchie de la valeur religieuse des actes.
B20: MON RADAR DE LA SEMAINE
B43: MON ANALYSE PERSONNALISÉE
B44: ① CE QUE TU FAIS BIEN
B45: =CALCULS!$C$47 -> Remplis ton suivi quotidien : ton analyse personnalisée apparaîtra ici automatiquement.
B47: ② CE QUE TU DOIS AMÉLIORER
B48: =CALCULS!$C$48 -> Aucune donnée pour l'instant.
B50: ③ TA MISSION DE LA SEMAINE PROCHAINE
B51: =CALCULS!$C$49 -> Commence par 2 ou 3 jours de suivi : ta mission apparaîtra ici.
B53: LE DÉTAIL DE MES INDICATEURS
B54: Indicateur | C54: Taux | E54: Ce que ça mesure
B55: Religion — habitudes recommandées | C55: =IF(CALCULS!L28="","—",CALCULS!L28) -> — | E55: Missions cochées « Fait » / missions actives renseignées (hors N/A).
B56: Religion — obligations | C56: =IF(CALCULS!L27="","—",CALCULS!L27) -> — | E56: Idem, pour les missions marquées « Obligation » dans l'onglet MISSIONS.
B57: Hydratation | C57: =IF(CALCULS!L9="","—",CALCULS!L9) -> — | E57: Litres bus / objectif personnel, plafonné à 100 % par jour.
B58: Repas équilibrés | C58: =IF(CALCULS!L10="","—",CALCULS!L10) -> — | E58: Repas équilibrés / objectif personnel, plafonné à 100 % par jour.
B59: Horaires de repas réguliers | C59: =IF(CALCULS!L11="","—",CALCULS!L11) -> — | E59: Jours « Oui » / jours Oui + Non.
B60: Durée de sommeil | C60: =IF(CALCULS!L15="","—",CALCULS!L15) -> — | E60: Heures dormies / objectif personnel, plafonné à 100 %.
B61: Heure de coucher régulière | C61: =IF(CALCULS!L16="","—",CALCULS!L16) -> — | E61: Couchers dans la plage visée (± tolérance) / couchers renseignés.
B62: Routine de récupération | C62: =IF(CALCULS!L17="","—",CALCULS!L17) -> — | E62: Jours « Oui » / jours Oui + Non.
B63: Minutes d'activité | C63: =IF(CALCULS!L21="","—",CALCULS!L21) -> — | E63: Minutes / objectif par jour actif, plafonné à 100 %.
B64: Séances prévues réalisées | C64: =IF(CALCULS!L22="","—",CALCULS!L22) -> — | E64: Séances réalisées / séances prévues.
B65: Régularité hebdomadaire | C65: =IF(CALCULS!L23="","—",CALCULS!L23) -> — | E65: Jours actifs / jours actifs visés, plafonné à 100 %.
B67: À REPORTER DANS « MA PROGRESSION »
B68: Semaine | C68: Religion | D68: Nutrition | E68: Sommeil | F68: Sport | G68: Score /100
B69: ='MON SUIVI QUOTIDIEN'!K6 | C69: =IF(CALCULS!C30="","",CALCULS!C30) | D69: =IF(CALCULS!C31="","",CALCULS!C31) | E69: =IF(CALCULS!C32="","",CALCULS!C32) | F69: =IF(CALCULS!C33="","",CALCULS!C33) | G69: =IF(CALCULS!$C$35=1,CALCULS!$C$36,"")
B70: En fin de semaine : sélectionne C à G de la ligne ci-dessus, Copier, puis dans MA PROGRESSION, sur la ligne de ta semaine : clic droit › Collage spécial › Valeurs.
B72: RAPPEL RIJAL FIT
...

Sheet MA PROGRESSION
B1: RIJAL FIT — EN ROUTE VERS LE RAMADAN
B2: TON CORPS AU SERVICE DE TA FOI
B3: MA PROGRESSION SEMAINE APRÈS SEMAINE
B4: Chaque fin de semaine, recopie (Collage spécial › Valeurs) la ligne « À reporter » de ton bilan. Les graphiques se mettent à jour seuls. Seule ta propre progression compte.
B5: Semaine | C5: Religion | D5: Nutrition | E5: Sommeil | F5: Sport | G5: Score /100 | H5: Ce que je retiens
B6: Semaine 1
B7: Semaine 2
B8: Semaine 3
B9: Semaine 4
B10: Semaine 5
B11: Semaine 6
B12: Semaine 7
B13: Semaine 8
B14: Semaine 9
B15: Semaine 10
B16: Semaine 11
B17: Semaine 12
... B29: Semaine 24

Sheet MES MISSIONS
B1: RIJAL FIT — EN ROUTE VERS LE RAMADAN
B2: TON CORPS AU SERVICE DE TA FOI
B3: MES MISSIONS : 30 HABITUDES SUR 24 SEMAINES
B4: Semaine 1 : une nouvelle mission chaque jour (J1 à J7). Ensuite : une seule nouvelle mission par semaine, jusqu'à la semaine 24. Chaque mission s'ajoute toute seule à ton suivi quotidien le jour indiqué, et tu la gardes jusqu'à la fin. Les récompenses citées sont le sens de hadiths dont la référence est donnée : elles t'encouragent, elles ne sont jamais une note sur ta foi.
B5: Sem. | C5: Dès | D5: Mission | E5: Comment la faire | F5: Récompense (sens du hadith) | G5: Source | H5: Statut
B6: =IF(MISSIONS!$C8="","",INT((MISSIONS!$C8-1)/7)+1) -> 1 | C6: =IF(MISSIONS!$C8="","","J"&MISSIONS!$C8) -> J1 | D6: =IF(MISSIONS!$D8="","",MISSIONS!$D8) -> Lire les 10 versets de la semaine | E6: =IF(MISSIONS!$F8="","",MISSIONS!$F8) -> Onglet VERSETS : lis les 10 versets de ta semaine avec leur traduction, lentement. Tu peux les relire chaque jour : la régularité compte plus que la quantité. | F6: =IF(MISSIONS!$G8="","",MISSIONS!$G8) -> Le Prophète ﷺ a dit : « Celui qui lit une lettre du Livre d'Allah aura une bonne action, et la bonne action est multipliée par dix. » | G6: =IF(MISSIONS!$H8="","",MISSIONS!$H8) -> At-Tirmidhi 2910 (hasan) | H6: =IF(OR(MISSIONS!$C8="",'MON SUIVI QUOTIDIEN'!$K$22=""),"",IF(MISSIONS!$C8<='MON SUIVI QUOTIDIEN'!$K$22,"Active","À venir"))
B7: =IF(MISSIONS!$C9="","",INT((MISSIONS!$C9-1)/7)+1) -> 1 | C7: =IF(MISSIONS!$C9="","","J"&MISSIONS!$C9) -> J2 | D7: =IF(MISSIONS!$D9="","",MISSIONS!$D9) -> Dire l'invocation du réveil | E7: =IF(MISSIONS!$F9="","",MISSIONS!$F9) -> À dire dès le réveil, avant de prendre son téléphone. « Al-ḥamdu lillāhi lladhī aḥyānā baʿda mā amātanā wa ilayhi n-nushūr » (الحمد لله الذي أحيانا بعد ما أماتنا وإليه النشور). | F7: =IF(MISSIONS!$G9="","",MISSIONS!$G9) -> Le Prophète ﷺ disait au réveil : « Louange à Allah qui nous a redonné la vie après nous avoir fait mourir, et c'est vers Lui que sera la résurrection. » Le sommeil est une petite mort : te réveiller est une raison de remercier Allah dès la première minute. Aucune récompense chiffrée n'est précisée : on s'en tient à ce que dit le texte. | G7: =IF(MISSIONS!$H9="","",MISSIONS!$H9) -> Boukhari 6312 ; Mouslim 2711 | H7: =IF(OR(MISSIONS!$C9="",'MON SUIVI QUOTIDIEN'!$K$22=""),"",IF(MISSIONS!$C9<='MON SUIVI QUOTIDIEN'!$K$22,"Active","À venir"))
B8: =IF(MISSIONS!$C10="","",INT((MISSIONS!$C10-1)/7)+1) -> 1 | C8: =IF(MISSIONS!$C10="","","J"&MISSIONS!$C10) -> J3 | D8: =IF(MISSIONS!$D10="","",MISSIONS!$D10) -> Renouveler mon intention pour Allah dans mes activités | E8: =IF(MISSIONS!$F10="","",MISSIONS!$F10) -> Travail, repas, sport, famille : faire de l'ordinaire une adoration. Un instant, avant l'activité : « Je le fais pour Allah ». | F8: =IF(MISSIONS!$G10="","",MISSIONS!$G10) -> Le Prophète ﷺ a dit : « Tu seras récompensé pour tout ce que tu dépenses pour Allah, même pour la bouchée que tu mets dans la bouche de ton épouse. » Une habitude de tous les jours devient une adoration quand l'intention est pour Allah. | G8: =IF(MISSIONS!$H10="","",MISSIONS!$H10) -> Boukhari 56 ; Boukhari 1 (« les actes ne valent que par les intentions ») | H8: =IF(OR(MISSIONS!$C10="",'MON SUIVI QUOTIDIEN'!$K$22=""),"",IF(MISSIONS!$C10<='MON SUIVI QUOTIDIEN'!$K$22,"Active","À venir"))
B9: =IF(MISSIONS!$C11="","",INT((MISSIONS!$C11-1)/7)+1) -> 1 | C9: =IF(MISSIONS!$C11="","","J"&MISSIONS!$C11) -> J4 | D9: =IF(MISSIONS!$D11="","",MISSIONS!$D11) -> Bon soupçon envers les autres et sourires sincères | E9: =IF(MISSIONS!$F11="","",MISSIONS!$F11) -> Chercher l'excuse avant le reproche ; sourire à ceux qu'on croise. | F9: =IF(MISSIONS!$G11="","",MISSIONS!$G11) -> « Ton sourire au visage de ton frère est une aumône. » Et : « Gardez-vous du soupçon, car le soupçon est le plus mensonger des discours. » | G9: =IF(MISSIONS!$H11="","",MISSIONS!$H11) -> At-Tirmidhi 1956 (hasan) ; Boukhari 6066 | H9: =IF(OR(MISSIONS!$C11="",'MON SUIVI QUOTIDIEN'!$K$22=""),"",IF(MISSIONS!$C11<='MON SUIVI QUOTIDIEN'!$K$22,"Active","À venir"))
B10: =IF(MISSIONS!$C12="","",INT((MISSIONS!$C12-1)/7)+1) -> 1 | C10: =IF(MISSIONS!$C12="","","J"&MISSIONS!$C12) -> J5 | D10: =IF(MISSIONS!$D12="","",MISSIONS!$D12) -> Prononcer 100 fois « Astaghfirullah » | E10: =IF(MISSIONS!$F12="","",MISSIONS!$F12) -> Avec une intention sincère, à un moment fixe de la journée. (أستغفر الله) | F10: =IF(MISSIONS!$G12="","",MISSIONS!$G12) -> Le Prophète ﷺ a dit : « Il y a parfois comme un voile sur mon cœur, et je demande pardon à Allah cent fois par jour. » | G10: =IF(MISSIONS!$H12="","",MISSIONS!$H12) -> Mouslim 2702 | H10: =IF(OR(MISSIONS!$C12="",'MON SUIVI QUOTIDIEN'!$K$22=""),"",IF(MISSIONS!$C12<='MON SUIVI QUOTIDIEN'!$K$22,"Active","À venir"))
B11: =IF(MISSIONS!$C13="","",INT((MISSIONS!$C13-1)/7)+1) -> 1 | C11: =IF(MISSIONS!$C13="","","J"&MISSIONS!$C13) -> J6 | D11: =IF(MISSIONS!$D13="","",MISSIONS!$D13) -> Dire 100 fois « Subḥān Allāh wa bi-ḥamdih » | E11: =IF(MISSIONS!$F13="","",MISSIONS!$F13) -> Formule : « Subḥāna Llāhi wa bi-ḥamdih » (سبحان الله وبحمده). Accroche-la à un moment fixe, par exemple après la prière du matin. | F11: =IF(MISSIONS!$G13="","",MISSIONS!$G13) -> Le Prophète ﷺ a dit : « Celui qui dit « Subḥāna Llāhi wa bi-ḥamdih » cent fois par jour, ses péchés lui sont pardonnés, même s'ils sont comme l'écume de la mer. » | G11: =IF(MISSIONS!$H13="","",MISSIONS!$H13) -> Boukhari 6405 | H11: =IF(OR(MISSIONS!$C13="",'MON SUIVI QUOTIDIEN'!$K$22=""),"",IF(MISSIONS!$C13<='MON SUIVI QUOTIDIEN'!$K$22,"Active","À venir"))
B12: =IF(MISSIONS!$C14="","",INT((MISSIONS!$C14-1)/7)+1) -> 1 | C12: =IF(MISSIONS!$C14="","","J"&MISSIONS!$C14) -> J7 | D12: =IF(MISSIONS!$D14="","",MISSIONS!$D14) -> Envoyer 10 fois des salutations sur le Prophète ﷺ | E12: =IF(MISSIONS!$F14="","",MISSIONS!$F14) -> Formule simple : « Allāhumma ṣalli ʿalā Muḥammad » ou « Ṣallā Llāhu ʿalayhi wa sallam ». Le vendredi, multiplie-les. | F12: =IF(MISSIONS!$G14="","",MISSIONS!$G14) -> Le Prophète ﷺ a dit : « Celui qui prie sur moi une fois, Allah priera sur lui dix fois. » | G12: =IF(MISSIONS!$H14="","",MISSIONS!$H14) -> Mouslim 408 | H12: =IF(OR(MISSIONS!$C14="",'MON SUIVI QUOTIDIEN'!$K$22=""),"",IF(MISSIONS!$C14<='MON SUIVI QUOTIDIEN'!$K$22,"Active","À venir"))
B13: =IF(MISSIONS!$C15="","",INT((MISSIONS!$C15-1)/7)+1) -> 2 | C13: =IF(MISSIONS!$C15="","","J"&MISSIONS!$C15) -> J8 | D13: =IF(MISSIONS!$D15="","",MISSIONS!$D15) -> Invoquer Allah de m'accorder le Ramadan | E13: =IF(MISSIONS!$F15="","",MISSIONS!$F15) -> Une fois par jour, dis simplement : « Ô Allah, fais-moi atteindre le Ramadan, et accepte-le de moi. » C'est la pratique des pieux prédécesseurs, que tu continueras jusqu'au Ramadan. | F13: =IF(MISSIONS!$G15="","",MISSIONS!$G15) -> Les pieux prédécesseurs invoquaient Allah pendant six mois pour atteindre le Ramadan, puis pendant six mois pour qu'Il l'accepte d'eux. | G13: =IF(MISSIONS!$H15="","",MISSIONS!$H15) -> Muʿallâ ibn al-Faḍl, rapporté par Ibn Rajab, Laṭâʾif al-Maʿârif (récit des pieux prédécesseurs, pas un hadith) | H13: =IF(OR(MISSIONS!$C15="",'MON SUIVI QUOTIDIEN'!$K$22=""),"",IF(MISSIONS!$C15<='MON SUIVI QUOTIDIEN'!$K$22,"Active","À venir"))
B14: =IF(MISSIONS!$C16="","",INT((MISSIONS!$C16-1)/7)+1) -> 3 | C14: =IF(MISSIONS!$C16="","","J"&MISSIONS!$C16) -> J15 | D14: =IF(MISSIONS!$D16="","",MISSIONS!$D16) -> Réciter 3 fois la sourate al-Ikhlâs (matin et soir) | E14: =IF(MISSIONS!$F16="","",MISSIONS!$F16) -> Le matin et le soir, 3 fois chaque fois. Une récitation équivaut à un tiers du Coran en récompense : 3 récitations en font donc l'équivalent d'un Coran entier. L'équivalence concerne la récompense : elle ne dispense pas de lire le Coran. | F14: =IF(MISSIONS!$G16="","",MISSIONS!$G16) -> Le Prophète ﷺ a dit : « Par Celui qui tient mon âme dans Sa main, cette sourate (Dis : Il est Allah, Unique) équivaut à un tiers du Coran ! » (Trois récitations = trois tiers = un Coran entier en récompense.) | G14: =IF(MISSIONS!$H16="","",MISSIONS!$H16) -> Boukhari 5013 ; Mouslim 811 | H14: =IF(OR(MISSIONS!$C16="",'MON SUIVI QUOTIDIEN'!$K$22=""),"",IF(MISSIONS!$C16<='MON SUIVI QUOTIDIEN'!$K$22,"Active","À venir"))
B15: =IF(MISSIONS!$C17="","",INT((MISSIONS!$C17-1)/7)+1) -> 4 | C15: =IF(MISSIONS!$C17="","","J"&MISSIONS!$C17) -> J22 | D15: =IF(MISSIONS!$D17="","",MISSIONS!$D17) -> Réciter al-Falaq et an-Nâs (matin et soir) | E15: =IF(MISSIONS!$F17="","",MISSIONS!$F17) -> Avec al-Ikhlâs que tu récites déjà : les trois dernières sourates, 3 fois le matin et le soir. Avant de dormir, souffle dans tes mains en les récitant puis passe-les sur ton corps. | F15: =IF(MISSIONS!$G17="","",MISSIONS!$G17) -> Le Prophète ﷺ a dit : « Dis : « Il est Allah, Unique » et les deux protectrices (al-Falaq et an-Nâs) le soir et le matin, trois fois : cela te suffira contre tout. » Il les récitait aussi avant de dormir, puis passait ses mains sur son corps. | G15: =IF(MISSIONS!$H17="","",MISSIONS!$H17) -> Abou Dawoud 5082 (hasan) ; Boukhari 5017 | H15: =IF(OR(MISSIONS!$C17="",'MON SUIVI QUOTIDIEN'!$K$22=""),"",IF(MISSIONS!$C17<='MON SUIVI QUOTIDIEN'!$K$22,"Active","À venir"))
B16: =IF(MISSIONS!$C18="","",INT((MISSIONS!$C18-1)/7)+1) -> 5 | C16: =IF(MISSIONS!$C18="","","J"&MISSIONS!$C18) -> J29 | D16: =IF(MISSIONS!$D18="","",MISSIONS!$D18) -> Réciter Âyat al-Kursî avant de dormir | E16: =IF(MISSIONS!$F18="","",MISSIONS!$F18) -> Avant de dormir, récite le verset 2:255 en entier (le verset du Trône). | F16: =IF(MISSIONS!$G18="","",MISSIONS!$G18) -> Le Prophète ﷺ a confirmé la parole : « Quand tu vas te coucher, récite Âyat al-Kursî jusqu'à la fin : un gardien d'Allah restera auprès de toi et aucun démon ne s'approchera de toi jusqu'au matin. » | G16: =IF(MISSIONS!$H18="","",MISSIONS!$H18) -> Boukhari 2311 ; Boukhari 5010 | H16: =IF(OR(MISSIONS!$C18="",'MON SUIVI QUOTIDIEN'!$K$22=""),"",IF(MISSIONS!$C18<='MON SUIVI QUOTIDIEN'!$K$22,"Active","À venir"))
B17: =IF(MISSIONS!$C19="","",INT((MISSIONS!$C19-1)/7)+1) -> 6 | C17: =IF(MISSIONS!$C19="","","J"&MISSIONS!$C19) -> J36 | D17: =IF(MISSIONS!$D19="","",MISSIONS!$D19) -> Ablutions soignées puis témoignage de foi | E17: =IF(MISSIONS!$F19="","",MISSIONS!$F19) -> Fais tes ablutions avec calme et soin, puis dis : « Ashhadu an lā ilāha illa Llāh waḥdahu lā sharīka lah, wa ashhadu anna Muḥammadan ʿabduhu wa rasūluh ». | F17: =IF(MISSIONS!$G19="","",MISSIONS!$G19) -> Le Prophète ﷺ a dit : « Celui qui fait bien ses ablutions puis dit « J'atteste qu'il n'y a de divinité qu'Allah et que Muhammad est Son serviteur et Son Messager », les huit portes du Paradis lui sont ouvertes : il entre par celle qu'il veut. » Et : « Si un musulman fait bien ses ablutions puis prie deux rakʿât en y mettant son cœur et son visage, le Paradis lui est garanti. » | G17: =IF(MISSIONS!$H19="","",MISSIONS!$H19) -> Mouslim 234 | H17: =IF(OR(MISSIONS!$C19="",'MON SUIVI QUOTIDIEN'!$K$22=""),"",IF(MISSIONS!$C19<='MON SUIVI QUOTIDIEN'!$K$22,"Active","À venir"))
... B45: =IF(MISSIONS!$C47="","",INT((MISSIONS!$C47-1)/7)+1) | C45: =IF(MISSIONS!$C47="","","J"&MISSIONS!$C47) | D45: =IF(MISSIONS!$D47="","",MISSIONS!$D47) | E45: =IF(MISSIONS!$F47="","",MISSIONS!$F47) | F45: =IF(MISSIONS!$G47="","",MISSIONS!$G47) | G45: =IF(MISSIONS!$H47="","",MISSIONS!$H47) | H45: =IF(OR(MISSIONS!$C47="",'MON SUIVI QUOTIDIEN'!$K$22=""),"",IF(MISSIONS!$C47<='MON SUIVI QUOTIDIEN'!$K$22,"Active","À venir"))

Sheet VERSETS
B1: RIJAL FIT — EN ROUTE VERS LE RAMADAN
B2: TON CORPS AU SERVICE DE TA FOI
B3: 10 VERSETS PAR SEMAINE, SUR 24 SEMAINES. Lis-les lentement, relis-les dans la semaine, médite un verset à la fois : mieux vaut peu de versets compris que beaucoup lus vite. Ta semaine en cours est surlignée. Traduction : Muhammad Hamidullah (sens approché du texte arabe).
B4: =IF(ISNUMBER('MON SUIVI QUOTIDIEN'!$K$6),'MON SUIVI QUOTIDIEN'!$K$6,"") | C4: =IF($B$4="","Renseigne la date de début dans MON SUIVI QUOTIDIEN : tes versets de la semaine seront surlignés ici.",IF($B$4<1,"Le challenge n'a pas encore commencé.",IF($B$4>24,"Tu as terminé les 24 semaines : qu'Allah accepte ton effort.","Cette semaine : "&INDEX($C$6:$C$245,($B$4-1)*10+1)))) -> Renseigne la date de début dans MON SUIVI QUOTIDIEN : tes versets de la semaine seront surlignés ici.
B5: Sem. | C5: Thème de la semaine | D5: Référence | E5: Verset (texte arabe) | F5: Traduction (français)
B6: 1 | C6: Louange et Unicité | D6: Al-Fatihah 1:1 | E6: بِسْمِ ٱللَّهِ ٱلرَّحْمَـٰنِ ٱلرَّحِيمِ | F6: Au nom d’Allah, le Tout Miséricordieux, le Très Miséricordieux.
B7: 1 | C7: Louange et Unicité | D7: Al-Fatihah 1:2 | E7: ٱلْحَمْدُ لِلَّهِ رَبِّ ٱلْعَـٰلَمِينَ | F7: Louange à Allah, Seigneur de l’Univers.
B8: 1 | C8: Louange et Unicité | D8: Al-Fatihah 1:3 | E8: ٱلرَّحْمَـٰنِ ٱلرَّحِيمِ | F8: Le Tout Miséricordieux, le Très Miséricordieux,
B9: 1 | C9: Louange et Unicité | D9: Al-Fatihah 1:4 | E9: مَـٰلِكِ يَوْمِ ٱلدِّينِ | F9: Maître du Jour de la Rétribution.
B10: 1 | C10: Louange et Unicité | D10: Al-Fatihah 1:5 | E10: إِيَّاكَ نَعْبُدُ وَإِيَّاكَ نَسْتَعِينُ | F10: C’est Toi [Seul] que nous adorons, et c’est Toi [Seul] dont nous implorons secours.
B11: 1 | C11: Louange et Unicité | D11: Al-Fatihah 1:6 | E11: ٱهْدِنَا ٱلصِّرَٰطَ ٱلْمُسْتَقِيمَ | F11: Guide-nous dans le droit chemin,
B12: 1 | C12: Louange et Unicité | D12: Al-Fatihah 1:7 | E12: صِرَٰطَ ٱلَّذِينَ أَنْعَمْتَ عَلَيْهِمْ غَيْرِ ٱلْمَغْضُوبِ عَلَيْهِمْ وَلَا ٱلضَّآلِّينَ | F12: Le chemin de ceux que Tu as comblés de faveurs, non pas de ceux qui ont encouru Ta colère, ni des égarés.
B13: 1 | C13: Louange et Unicité | D13: Al-Ikhlas 112:1 | E13: قُلْ هُوَ ٱللَّهُ أَحَدٌ | F13: Dis : "Il est Allah, Unique.
B14: 1 | C14: Louange et Unicité | D14: Al-Ikhlas 112:2 | E14: ٱللَّهُ ٱلصَّمَدُ | F14: Allah, Le Seul à être imploré pour ce que nous désirons.
B15: 1 | C15: Louange et Unicité | D15: Al-Ikhlas 112:3 | E15: لَمْ يَلِدْ وَلَمْ يُولَدْ | F15: Il n’a jamais engendré, n’a pas été engendré non plus.
B16: 2 | C16: Le rappel d'Allah | D16: Al-Baqarah 2:152 | E16: فَٱذْكُرُونِىٓ أَذْكُرْكُمْ وَٱشْكُرُوا۟ لِى وَلَا تَكْفُرُونِ | F16: Souvenez-vous de Moi donc, Je Me souviendrai de vous. Remerciez- Moi et ne soyez pas ingrats envers Moi !
B17: 2 | C17: Le rappel d'Allah | D17: Al-Baqarah 2:153 | E17: يَـٰٓأَيُّهَا ٱلَّذِينَ ءَامَنُوا۟ ٱسْتَعِينُوا۟ بِٱلصَّبْرِ وَٱلصَّلَوٰةِ ۚ إِنَّ ٱللَّهَ مَعَ ٱلصَّـٰبِرِينَ | F17: Ô les croyants! Cherchez assistance dans l’endurance et la prière (Aṣ-Ṣalāt). Car Allah est avec les endurants.
... B245: 24 | C245: Atteindre le Ramadan | D245: Nuh 71:28 | E245: رَّبِّ ٱغْفِرْ لِى وَلِوَٰلِدَىَّ وَلِمَن دَخَلَ بَيْتِىَ مُؤْمِنًا وَلِلْمُؤْمِنِينَ وَٱلْمُؤْمِنَـٰتِ وَلَا تَزِدِ ٱلظَّـٰلِمِينَ إِلَّا تَبَارًۢا | F245: Seigneur! Pardonne-moi, et à mes père et mère et à celui qui entre dans ma demeure croyant, ainsi qu’aux croyants et croyantes; et ne fait croître les injustes qu’en perdition."

Sheet MISSIONS
B1: RIJAL FIT — EN ROUTE VERS LE RAMADAN
B2: TON CORPS AU SERVICE DE TA FOI
B3: ESPACE COACH — MISSIONS RELIGIEUSES ET RÉGLAGES
B4: Jours renseignés minimum par pilier pour un bilan complet (sur 7) | E4: 4
B5: En dessous de ce nombre de jours renseignés dans un pilier, le bilan est signalé « incomplet » et le score global n'est pas affiché. Une case vide n'est jamais comptée comme un échec.
B6: LISTE DES MISSIONS : J1 à J7 une mission par jour, puis une nouvelle mission chaque semaine. Tu peux en ajouter jusqu'à 40 (ligne suivante libre, dans l'ordre des jours).
B7: N° | C7: Jour d'intro (J…) | D7: Mission (texte court) | E7: Nature | F7: Précision / conseil | G7: Récompense (sens du hadith) | H7: Source
B8: 1 | C8: 1 | D8: Lire les 10 versets de la semaine | E8: Habitude recommandée | F8: Onglet VERSETS : lis les 10 versets de ta semaine avec leur traduction, lentement. Tu peux les relire chaque jour : la régularité compte plus que la quantité. | G8: Le Prophète ﷺ a dit : « Celui qui lit une lettre du Livre d'Allah aura une bonne action, et la bonne action est multipliée par dix. » | H8: At-Tirmidhi 2910 (hasan)
B9: 2 | C9: 2 | D9: Dire l'invocation du réveil | E9: Habitude recommandée | F9: À dire dès le réveil, avant de prendre son téléphone. « Al-ḥamdu lillāhi lladhī aḥyānā baʿda mā amātanā wa ilayhi n-nushūr » (الحمد لله الذي أحيانا بعد ما أماتنا وإليه النشور). | G9: Le Prophète ﷺ disait au réveil : « Louange à Allah qui nous a redonné la vie après nous avoir fait mourir, et c'est vers Lui que sera la résurrection. » Le sommeil est une petite mort : te réveiller est une raison de remercier Allah dès la première minute. Aucune récompense chiffrée n'est précisée : on s'en tient à ce que dit le texte. | H9: Boukhari 6312 ; Mouslim 2711
B10: 3 | C10: 3 | D10: Renouveler mon intention pour Allah dans mes activités | E10: Habitude recommandée | F10: Travail, repas, sport, famille : faire de l'ordinaire une adoration. Un instant, avant l'activité : « Je le fais pour Allah ». | G10: Le Prophète ﷺ a dit : « Tu seras récompensé pour tout ce que tu dépenses pour Allah, même pour la bouchée que tu mets dans la bouche de ton épouse. » Une habitude de tous les jours devient une adoration quand l'intention est pour Allah. | H10: Boukhari 56 ; Boukhari 1 (« les actes ne valent que par les intentions »)
B11: 4 | C11: 4 | D11: Bon soupçon envers les autres et sourires sincères | E11: Habitude recommandée | F11: Chercher l'excuse avant le reproche ; sourire à ceux qu'on croise. | G11: « Ton sourire au visage de ton frère est une aumône. » Et : « Gardez-vous du soupçon, car le soupçon est le plus mensonger des discours. » | H11: At-Tirmidhi 1956 (hasan) ; Boukhari 6066
B12: 5 | C12: 5 | D12: Prononcer 100 fois « Astaghfirullah » | E12: Habitude recommandée | F12: Avec une intention sincère, à un moment fixe de la journée. (أستغفر الله) | G12: Le Prophète ﷺ a dit : « Il y a parfois comme un voile sur mon cœur, et je demande pardon à Allah cent fois par jour. » | H12: Mouslim 2702
B13: 6 | C13: 6 | D13: Dire 100 fois « Subḥān Allāh wa bi-ḥamdih » | E13: Habitude recommandée | F13: Formule : « Subḥāna Llāhi wa bi-ḥamdih » (سبحان الله وبحمده). Accroche-la à un moment fixe, par exemple après la prière du matin. | G13: Le Prophète ﷺ a dit : « Celui qui dit « Subḥāna Llāhi wa bi-ḥamdih » cent fois par jour, ses péchés lui sont pardonnés, même s'ils sont comme l'écume de la mer. » | H13: Boukhari 6405
B14: 7 | C14: 7 | D14: Envoyer 10 fois des salutations sur le Prophète ﷺ | E14: Habitude recommandée | F14: Formule simple : « Allāhumma ṣalli ʿalā Muḥammad » ou « Ṣallā Llāhu ʿalayhi wa sallam ». Le vendredi, multiplie-les. | G14: Le Prophète ﷺ a dit : « Celui qui prie sur moi une fois, Allah priera sur lui dix fois. » | H14: Mouslim 408
B15: 8 | C15: 8 | D15: Invoquer Allah de m'accorder le Ramadan | E15: Habitude recommandée | F15: Une fois par jour, dis simplement : « Ô Allah, fais-moi atteindre le Ramadan, et accepte-le de moi. » C'est la pratique des pieux prédécesseurs, que tu continueras jusqu'au Ramadan. | G15: Les pieux prédécesseurs invoquaient Allah pendant six mois pour atteindre le Ramadan, puis pendant six mois pour qu'Il l'accepte d'eux. | H15: Muʿallâ ibn al-Faḍl, rapporté par Ibn Rajab, Laṭâʾif al-Maʿârif (récit des pieux prédécesseurs, pas un hadith)
B16: 9 | C16: 15 | D16: Réciter 3 fois la sourate al-Ikhlâs (matin et soir) | E16: Habitude recommandée | F16: Le matin et le soir, 3 fois chaque fois. Une récitation équivaut à un tiers du Coran en récompense : 3 récitations en font donc l'équivalent d'un Coran entier. L'équivalence concerne la récompense : elle ne dispense pas de lire le Coran. | G16: Le Prophète ﷺ a dit : « Par Celui qui tient mon âme dans Sa main, cette sourate (Dis : Il est Allah, Unique) équivaut à un tiers du Coran ! » (Trois récitations = trois tiers = un Coran entier en récompense.) | H16: Boukhari 5013 ; Mouslim 811
B17: 10 | C17: 22 | D17: Réciter al-Falaq et an-Nâs (matin et soir) | E17: Habitude recommandée | F17: Avec al-Ikhlâs que tu récites déjà : les trois dernières sourates, 3 fois le matin et le soir. Avant de dormir, souffle dans tes mains en les récitant puis passe-les sur ton corps. | G17: Le Prophète ﷺ a dit : « Dis : « Il est Allah, Unique » et les deux protectrices (al-Falaq et an-Nâs) le soir et le matin, trois fois : cela te suffira contre tout. » Il les récitait aussi avant de dormir, puis passait ses mains sur son corps. | H17: Abou Dawoud 5082 (hasan) ; Boukhari 5017
B18: 11 | C18: 29 | D18: Réciter Âyat al-Kursî avant de dormir | E18: Habitude recommandée | F18: Avant de dormir, récite le verset 2:255 en entier (le verset du Trône). | G18: Le Prophète ﷺ a confirmé la parole : « Quand tu vas te coucher, récite Âyat al-Kursî jusqu'à la fin : un gardien d'Allah restera auprès de toi et aucun démon ne s'approchera de toi jusqu'au matin. » | H18: Boukhari 2311 ; Boukhari 5010
B19: 12 | C19: 36 | D19: Ablutions soignées puis témoignage de foi | E19: Habitude recommandée | F19: Fais tes ablutions avec calme et soin, puis dis : « Ashhadu an lā ilāha illa Llāh waḥdahu lā sharīka lah, wa ashhadu anna Muḥammadan ʿabduhu wa rasūluh ». | G19: Le Prophète ﷺ a dit : « Celui qui fait bien ses ablutions puis dit « J'atteste qu'il n'y a de divinité qu'Allah et que Muhammad est Son serviteur et Son Messager », les huit portes du Paradis lui sont ouvertes : il entre par celle qu'il veut. » Et : « Si un musulman fait bien ses ablutions puis prie deux rakʿât en y mettant son cœur et son visage, le Paradis lui est garanti. » | H19: Mouslim 234
... B37: 30 | C37: 162 | D37: Demander pardon à ceux que j'ai lésés | E37: Habitude recommandée | F37: À faire avant d'entrer dans le Ramadan : réconcilie-toi, rembourse ce que tu dois. Une fois que tu es en paix avec les gens, le Ramadan peut commencer. Et prépare ta prière de nuit pour le Ramadan (Boukhari 37 : « Celui qui accomplit la prière de nuit en Ramadan avec foi et en espérant la récompense, ses péchés passés lui sont pardonnés »). | G37: Le Prophète ﷺ a dit : « Celui qui a lésé son frère dans son honneur ou autrement, qu'il lui demande pardon dès aujourd'hui, avant le jour où il n'y aura ni dinar ni dirham : on prendra de ses bonnes actions à hauteur de son injustice. » | H37: Boukhari 2449 ; Boukhari 37
B38: 31
B39: 32
B40: 33
B41: 34
B42: 35
B43: 36
B44: 37
B45: 38
B46: 39
B47: 40
B49: Nature : « Obligation » pour un acte obligatoire (ex. une prière), « Habitude recommandée » pour un acte facultatif. Les deux sont suivis comme des habitudes de régularité. Le fichier ne note jamais la sincérité ni la qualité de la foi. Les colonnes Récompense et Source donnent le sens des hadiths cités avec leur référence : en cas de doute, vérifie auprès d'une personne de science avant de modifier.

Sheet CALCULS
B1: Feuille de calcul technique — ne pas modifier (masquée)
E2: Lun | F2: Mar | G2: Mer | H2: Jeu | I2: Ven | J2: Sam | K2: Dim | L2: Semaine
B3: Religion — fait | E3: =SUMPRODUCT(('MON SUIVI QUOTIDIEN'!E$28:E$67="Fait")*('MON SUIVI QUOTIDIEN'!$E$22>='MON SUIVI QUOTIDIEN'!$C$28:$C$67)*('MON SUIVI QUOTIDIEN'!$C$28:$C$67<>"")) -> 0 | F3: =SUMPRODUCT(('MON SUIVI QUOTIDIEN'!F$28:F$67="Fait")*('MON SUIVI QUOTIDIEN'!$F$22>='MON SUIVI QUOTIDIEN'!$C$28:$C$67)*('MON SUIVI QUOTIDIEN'!$C$28:$C$67<>"")) -> 0 | G3: =SUMPRODUCT(('MON SUIVI QUOTIDIEN'!G$28:G$67="Fait")*('MON SUIVI QUOTIDIEN'!$G$22>='MON SUIVI QUOTIDIEN'!$C$28:$C$67)*('MON SUIVI QUOTIDIEN'!$C$28:$C$67<>"")) -> 0 | H3: =SUMPRODUCT(('MON SUIVI QUOTIDIEN'!H$28:H$67="Fait")*('MON SUIVI QUOTIDIEN'!$H$22>='MON SUIVI QUOTIDIEN'!$C$28:$C$67)*('MON SUIVI QUOTIDIEN'!$C$28:$C$67<>"")) -> 0 | I3: =SUMPRODUCT(('MON SUIVI QUOTIDIEN'!I$28:I$67="Fait")*('MON SUIVI QUOTIDIEN'!$I$22>='MON SUIVI QUOTIDIEN'!$C$28:$C$67)*('MON SUIVI QUOTIDIEN'!$C$28:$C$67<>"")) -> 0 | J3: =SUMPRODUCT(('MON SUIVI QUOTIDIEN'!J$28:J$67="Fait")*('MON SUIVI QUOTIDIEN'!$J$22>='MON SUIVI QUOTIDIEN'!$C$28:$C$67)*('MON SUIVI QUOTIDIEN'!$C$28:$C$67<>"")) -> 0 | K3: =SUMPRODUCT(('MON SUIVI QUOTIDIEN'!K$28:K$67="Fait")*('MON SUIVI QUOTIDIEN'!$K$22>='MON SUIVI QUOTIDIEN'!$C$28:$C$67)*('MON SUIVI QUOTIDIEN'!$C$28:$C$67<>"")) -> 0 | L3: =SUM(E3:K3) -> 0
B4: Religion — pas fait | E4: =SUMPRODUCT(('MON SUIVI QUOTIDIEN'!E$28:E$67="Pas fait")*('MON SUIVI QUOTIDIEN'!$E$22>='MON SUIVI QUOTIDIEN'!$C$28:$C$67)*('MON SUIVI QUOTIDIEN'!$C$28:$C$67<>"")) -> 0 | F4: =SUMPRODUCT(('MON SUIVI QUOTIDIEN'!F$28:F$67="Pas fait")*('MON SUIVI QUOTIDIEN'!$F$22>='MON SUIVI QUOTIDIEN'!$C$28:$C$67)*('MON SUIVI QUOTIDIEN'!$C$28:$C$67<>"")) -> 0 | G4: =SUMPRODUCT(('MON SUIVI QUOTIDIEN'!G$28:G$67="Pas fait")*('MON SUIVI QUOTIDIEN'!$G$22>='MON SUIVI QUOTIDIEN'!$C$28:$C$67)*('MON SUIVI QUOTIDIEN'!$C$28:$C$67<>"")) -> 0 | H4: =SUMPRODUCT(('MON SUIVI QUOTIDIEN'!H$28:H$67="Pas fait")*('MON SUIVI QUOTIDIEN'!$H$22>='MON SUIVI QUOTIDIEN'!$C$28:$C$67)*('MON SUIVI QUOTIDIEN'!$C$28:$C$67<>"")) -> 0 | I4: =SUMPRODUCT(('MON SUIVI QUOTIDIEN'!I$28:I$67="Pas fait")*('MON SUIVI QUOTIDIEN'!$I$22>='MON SUIVI QUOTIDIEN'!$C$28:$C$67)*('MON SUIVI QUOTIDIEN'!$C$28:$C$67<>"")) -> 0 | J4: =SUMPRODUCT(('MON SUIVI QUOTIDIEN'!J$28:J$67="Pas fait")*('MON SUIVI QUOTIDIEN'!$J$22>='MON SUIVI QUOTIDIEN'!$C$28:$C$67)*('MON SUIVI QUOTIDIEN'!$C$28:$C$67<>"")) -> 0 | K4: =SUMPRODUCT(('MON SUIVI QUOTIDIEN'!K$28:K$67="Pas fait")*('MON SUIVI QUOTIDIEN'!$K$22>='MON SUIVI QUOTIDIEN'!$C$28:$C$67)*('MON SUIVI QUOTIDIEN'!$C$28:$C$67<>"")) -> 0 | L4: =SUM(E4:K4) -> 0
B5: Religion — N/A | E5: =SUMPRODUCT(('MON SUIVI QUOTIDIEN'!E$28:E$67="N/A")*('MON SUIVI QUOTIDIEN'!$E$22>='MON SUIVI QUOTIDIEN'!$C$28:$C$67)*('MON SUIVI QUOTIDIEN'!$C$28:$C$67<>"")) -> 0 | F5: =SUMPRODUCT(('MON SUIVI QUOTIDIEN'!F$28:F$67="N/A")*('MON SUIVI QUOTIDIEN'!$F$22>='MON SUIVI QUOTIDIEN'!$C$28:$C$67)*('MON SUIVI QUOTIDIEN'!$C$28:$C$67<>"")) -> 0 | G5: =SUMPRODUCT(('MON SUIVI QUOTIDIEN'!G$28:G$67="N/A")*('MON SUIVI QUOTIDIEN'!$G$22>='MON SUIVI QUOTIDIEN'!$C$28:$C$67)*('MON SUIVI QUOTIDIEN'!$C$28:$C$67<>"")) -> 0 | H5: =SUMPRODUCT(('MON SUIVI QUOTIDIEN'!H$28:H$67="N/A")*('MON SUIVI QUOTIDIEN'!$H$22>='MON SUIVI QUOTIDIEN'!$C$28:$C$67)*('MON SUIVI QUOTIDIEN'!$C$28:$C$67<>"")) -> 0 | I5: =SUMPRODUCT(('MON SUIVI QUOTIDIEN'!I$28:I$67="N/A")*('MON SUIVI QUOTIDIEN'!$I$22>='MON SUIVI QUOTIDIEN'!$C$28:$C$67)*('MON SUIVI QUOTIDIEN'!$C$28:$C$67<>"")) -> 0 | J5: =SUMPRODUCT(('MON SUIVI QUOTIDIEN'!J$28:J$67="N/A")*('MON SUIVI QUOTIDIEN'!$J$22>='MON SUIVI QUOTIDIEN'!$C$28:$C$67)*('MON SUIVI QUOTIDIEN'!$C$28:$C$67<>"")) -> 0 | K5: =SUMPRODUCT(('MON SUIVI QUOTIDIEN'!K$28:K$67="N/A")*('MON SUIVI QUOTIDIEN'!$K$22>='MON SUIVI QUOTIDIEN'!$C$28:$C$67)*('MON SUIVI QUOTIDIEN'!$C$28:$C$67<>"")) -> 0 | L5: =SUM(E5:K5) -> 0
B6: Religion — renseigné | E6: =E3+E4+E5 -> 0 | F6: =F3+F4+F5 -> 0 | G6: =G3+G4+G5 -> 0 | H6: =H3+H4+H5 -> 0 | I6: =I3+I4+I5 -> 0 | J6: =J3+J4+J5 -> 0 | K6: =K3+K4+K5 -> 0 | L6: =COUNTIF(E6:K6,">0") -> 0
B7: Religion — taux jour | E7: =IF(E3+E4=0,"",E3/(E3+E4)) | F7: =IF(F3+F4=0,"",F3/(F3+F4)) | G7: =IF(G3+G4=0,"",G3/(G3+G4)) | H7: =IF(H3+H4=0,"",H3/(H3+H4)) | I7: =IF(I3+I4=0,"",I3/(I3+I4)) | J7: =IF(J3+J4=0,"",J3/(J3+J4)) | K7: =IF(K3+K4=0,"",K3/(K3+K4)) | L7: =IF(L3+L4=0,"",L3/(L3+L4))
B9: Nutrition — hydratation (ratio) | E9: =IF(OR('MON SUIVI QUOTIDIEN'!E72="",'MON SUIVI QUOTIDIEN'!$C$12<=0),"",MIN(1,'MON SUIVI QUOTIDIEN'!E72/'MON SUIVI QUOTIDIEN'!$C$12)) | F9: =IF(OR('MON SUIVI QUOTIDIEN'!F72="",'MON SUIVI QUOTIDIEN'!$C$12<=0),"",MIN(1,'MON SUIVI QUOTIDIEN'!F72/'MON SUIVI QUOTIDIEN'!$C$12)) | G9: =IF(OR('MON SUIVI QUOTIDIEN'!G72="",'MON SUIVI QUOTIDIEN'!$C$12<=0),"",MIN(1,'MON SUIVI QUOTIDIEN'!G72/'MON SUIVI QUOTIDIEN'!$C$12)) | H9: =IF(OR('MON SUIVI QUOTIDIEN'!H72="",'MON SUIVI QUOTIDIEN'!$C$12<=0),"",MIN(1,'MON SUIVI QUOTIDIEN'!H72/'MON SUIVI QUOTIDIEN'!$C$12)) | I9: =IF(OR('MON SUIVI QUOTIDIEN'!I72="",'MON SUIVI QUOTIDIEN'!$C$12<=0),"",MIN(1,'MON SUIVI QUOTIDIEN'!I72/'MON SUIVI QUOTIDIEN'!$C$12)) | J9: =IF(OR('MON SUIVI QUOTIDIEN'!J72="",'MON SUIVI QUOTIDIEN'!$C$12<=0),"",MIN(1,'MON SUIVI QUOTIDIEN'!J72/'MON SUIVI QUOTIDIEN'!$C$12)) | K9: =IF(OR('MON SUIVI QUOTIDIEN'!K72="",'MON SUIVI QUOTIDIEN'!$C$12<=0),"",MIN(1,'MON SUIVI QUOTIDIEN'!K72/'MON SUIVI QUOTIDIEN'!$C$12)) | L9: =IF(COUNT(E9:K9)=0,"",AVERAGE(E9:K9))
B10: Nutrition — repas (ratio) | E10: =IF(OR('MON SUIVI QUOTIDIEN'!E74="",'MON SUIVI QUOTIDIEN'!$C$13<=0),"",MIN(1,'MON SUIVI QUOTIDIEN'!E74/'MON SUIVI QUOTIDIEN'!$C$13)) | F10: =IF(OR('MON SUIVI QUOTIDIEN'!F74="",'MON SUIVI QUOTIDIEN'!$C$13<=0),"",MIN(1,'MON SUIVI QUOTIDIEN'!F74/'MON SUIVI QUOTIDIEN'!$C$13)) | G10: =IF(OR('MON SUIVI QUOTIDIEN'!G74="",'MON SUIVI QUOTIDIEN'!$C$13<=0),"",MIN(1,'MON SUIVI QUOTIDIEN'!G74/'MON SUIVI QUOTIDIEN'!$C$13)) | H10: =IF(OR('MON SUIVI QUOTIDIEN'!H74="",'MON SUIVI QUOTIDIEN'!$C$13<=0),"",MIN(1,'MON SUIVI QUOTIDIEN'!H74/'MON SUIVI QUOTIDIEN'!$C$13)) | I10: =IF(OR('MON SUIVI QUOTIDIEN'!I74="",'MON SUIVI QUOTIDIEN'!$C$13<=0),"",MIN(1,'MON SUIVI QUOTIDIEN'!I74/'MON SUIVI QUOTIDIEN'!$C$13)) | J10: =IF(OR('MON SUIVI QUOTIDIEN'!J74="",'MON SUIVI QUOTIDIEN'!$C$13<=0),"",MIN(1,'MON SUIVI QUOTIDIEN'!J74/'MON SUIVI QUOTIDIEN'!$C$13)) | K10: =IF(OR('MON SUIVI QUOTIDIEN'!K74="",'MON SUIVI QUOTIDIEN'!$C$13<=0),"",MIN(1,'MON SUIVI QUOTIDIEN'!K74/'MON SUIVI QUOTIDIEN'!$C$13)) | L10: =IF(COUNT(E10:K10)=0,"",AVERAGE(E10:K10))
B11: Nutrition — horaires (1/0) | E11: =IF('MON SUIVI QUOTIDIEN'!E75="Oui",1,IF('MON SUIVI QUOTIDIEN'!E75="Non",0,"")) | F11: =IF('MON SUIVI QUOTIDIEN'!F75="Oui",1,IF('MON SUIVI QUOTIDIEN'!F75="Non",0,"")) | G11: =IF('MON SUIVI QUOTIDIEN'!G75="Oui",1,IF('MON SUIVI QUOTIDIEN'!G75="Non",0,"")) | H11: =IF('MON SUIVI QUOTIDIEN'!H75="Oui",1,IF('MON SUIVI QUOTIDIEN'!H75="Non",0,"")) | I11: =IF('MON SUIVI QUOTIDIEN'!I75="Oui",1,IF('MON SUIVI QUOTIDIEN'!I75="Non",0,"")) | J11: =IF('MON SUIVI QUOTIDIEN'!J75="Oui",1,IF('MON SUIVI QUOTIDIEN'!J75="Non",0,"")) | K11: =IF('MON SUIVI QUOTIDIEN'!K75="Oui",1,IF('MON SUIVI QUOTIDIEN'!K75="Non",0,"")) | L11: =IF(COUNT(E11:K11)=0,"",AVERAGE(E11:K11))
B12: Nutrition — renseigné | E12: =IF(COUNTA('MON SUIVI QUOTIDIEN'!E72,'MON SUIVI QUOTIDIEN'!E74,'MON SUIVI QUOTIDIEN'!E75)>0,1,0) -> 0 | F12: =IF(COUNTA('MON SUIVI QUOTIDIEN'!F72,'MON SUIVI QUOTIDIEN'!F74,'MON SUIVI QUOTIDIEN'!F75)>0,1,0) -> 0 | G12: =IF(COUNTA('MON SUIVI QUOTIDIEN'!G72,'MON SUIVI QUOTIDIEN'!G74,'MON SUIVI QUOTIDIEN'!G75)>0,1,0) -> 0 | H12: =IF(COUNTA('MON SUIVI QUOTIDIEN'!H72,'MON SUIVI QUOTIDIEN'!H74,'MON SUIVI QUOTIDIEN'!H75)>0,1,0) -> 0 | I12: =IF(COUNTA('MON SUIVI QUOTIDIEN'!I72,'MON SUIVI QUOTIDIEN'!I74,'MON SUIVI QUOTIDIEN'!I75)>0,1,0) -> 0 | J12: =IF(COUNTA('MON SUIVI QUOTIDIEN'!J72,'MON SUIVI QUOTIDIEN'!J74,'MON SUIVI QUOTIDIEN'!J75)>0,1,0) -> 0 | K12: =IF(COUNTA('MON SUIVI QUOTIDIEN'!K72,'MON SUIVI QUOTIDIEN'!K74,'MON SUIVI QUOTIDIEN'!K75)>0,1,0) -> 0 | L12: =SUM(E12:K12) -> 0
B13: Nutrition — taux jour | E13: =IF(COUNT(E9:E11)=0,"",AVERAGE(E9:E11)) | F13: =IF(COUNT(F9:F11)=0,"",AVERAGE(F9:F11)) | G13: =IF(COUNT(G9:G11)=0,"",AVERAGE(G9:G11)) | H13: =IF(COUNT(H9:H11)=0,"",AVERAGE(H9:H11)) | I13: =IF(COUNT(I9:I11)=0,"",AVERAGE(I9:I11)) | J13: =IF(COUNT(J9:J11)=0,"",AVERAGE(J9:J11)) | K13: =IF(COUNT(K9:K11)=0,"",AVERAGE(K9:K11)) | L13: =IF(COUNT(L9:L11)=0,"",AVERAGE(L9:L11))
B15: Sommeil — durée (ratio) | E15: =IF(OR('MON SUIVI QUOTIDIEN'!E80="",'MON SUIVI QUOTIDIEN'!$C$14<=0),"",MIN(1,'MON SUIVI QUOTIDIEN'!E80/'MON SUIVI QUOTIDIEN'!$C$14)) | F15: =IF(OR('MON SUIVI QUOTIDIEN'!F80="",'MON SUIVI QUOTIDIEN'!$C$14<=0),"",MIN(1,'MON SUIVI QUOTIDIEN'!F80/'MON SUIVI QUOTIDIEN'!$C$14)) | G15: =IF(OR('MON SUIVI QUOTIDIEN'!G80="",'MON SUIVI QUOTIDIEN'!$C$14<=0),"",MIN(1,'MON SUIVI QUOTIDIEN'!G80/'MON SUIVI QUOTIDIEN'!$C$14)) | H15: =IF(OR('MON SUIVI QUOTIDIEN'!H80="",'MON SUIVI QUOTIDIEN'!$C$14<=0),"",MIN(1,'MON SUIVI QUOTIDIEN'!H80/'MON SUIVI QUOTIDIEN'!$C$14)) | I15: =IF(OR('MON SUIVI QUOTIDIEN'!I80="",'MON SUIVI QUOTIDIEN'!$C$14<=0),"",MIN(1,'MON SUIVI QUOTIDIEN'!I80/'MON SUIVI QUOTIDIEN'!$C$14)) | J15: =IF(OR('MON SUIVI QUOTIDIEN'!J80="",'MON SUIVI QUOTIDIEN'!$C$14<=0),"",MIN(1,'MON SUIVI QUOTIDIEN'!J80/'MON SUIVI QUOTIDIEN'!$C$14)) | K15: =IF(OR('MON SUIVI QUOTIDIEN'!K80="",'MON SUIVI QUOTIDIEN'!$C$14<=0),"",MIN(1,'MON SUIVI QUOTIDIEN'!K80/'MON SUIVI QUOTIDIEN'!$C$14)) | L15: =IF(COUNT(E15:K15)=0,"",AVERAGE(E15:K15))
B16: Sommeil — coucher dans la plage | E16: =IF('MON SUIVI QUOTIDIEN'!E81="","",IF(MIN(ABS(MOD('MON SUIVI QUOTIDIEN'!E81,1)-MOD('MON SUIVI QUOTIDIEN'!$C$15,1)),1-ABS(MOD('MON SUIVI QUOTIDIEN'!E81,1)-MOD('MON SUIVI QUOTIDIEN'!$C$15,1)))*1440<='MON SUIVI QUOTIDIEN'!$C$16+0.01,1,0)) | F16: =IF('MON SUIVI QUOTIDIEN'!F81="","",IF(MIN(ABS(MOD('MON SUIVI QUOTIDIEN'!F81,1)-MOD('MON SUIVI QUOTIDIEN'!$C$15,1)),1-ABS(MOD('MON SUIVI QUOTIDIEN'!F81,1)-MOD('MON SUIVI QUOTIDIEN'!$C$15,1)))*1440<='MON SUIVI QUOTIDIEN'!$C$16+0.01,1,0)) | G16: =IF('MON SUIVI QUOTIDIEN'!G81="","",IF(MIN(ABS(MOD('MON SUIVI QUOTIDIEN'!G81,1)-MOD('MON SUIVI QUOTIDIEN'!$C$15,1)),1-ABS(MOD('MON SUIVI QUOTIDIEN'!G81,1)-MOD('MON SUIVI QUOTIDIEN'!$C$15,1)))*1440<='MON SUIVI QUOTIDIEN'!$C$16+0.01,1,0)) | H16: =IF('MON SUIVI QUOTIDIEN'!H81="","",IF(MIN(ABS(MOD('MON SUIVI QUOTIDIEN'!H81,1)-MOD('MON SUIVI QUOTIDIEN'!$C$15,1)),1-ABS(MOD('MON SUIVI QUOTIDIEN'!H81,1)-MOD('MON SUIVI QUOTIDIEN'!$C$15,1)))*1440<='MON SUIVI QUOTIDIEN'!$C$16+0.01,1,0)) | I16: =IF('MON SUIVI QUOTIDIEN'!I81="","",IF(MIN(ABS(MOD('MON SUIVI QUOTIDIEN'!I81,1)-MOD('MON SUIVI QUOTIDIEN'!$C$15,1)),1-ABS(MOD('MON SUIVI QUOTIDIEN'!I81,1)-MOD('MON SUIVI QUOTIDIEN'!$C$15,1)))*1440<='MON SUIVI QUOTIDIEN'!$C$16+0.01,1,0)) | J16: =IF('MON SUIVI QUOTIDIEN'!J81="","",IF(MIN(ABS(MOD('MON SUIVI QUOTIDIEN'!J81,1)-MOD('MON SUIVI QUOTIDIEN'!$C$15,1)),1-ABS(MOD('MON SUIVI QUOTIDIEN'!J81,1)-MOD('MON SUIVI QUOTIDIEN'!$C$15,1)))*1440<='MON SUIVI QUOTIDIEN'!$C$16+0.01,1,0)) | K16: =IF('MON SUIVI QUOTIDIEN'!K81="","",IF(MIN(ABS(MOD('MON SUIVI QUOTIDIEN'!K81,1)-MOD('MON SUIVI QUOTIDIEN'!$C$15,1)),1-ABS(MOD('MON SUIVI QUOTIDIEN'!K81,1)-MOD('MON SUIVI QUOTIDIEN'!$C$15,1)))*1440<='MON SUIVI QUOTIDIEN'!$C$16+0.01,1,0)) | L16: =IF(COUNT(E16:K16)=0,"",AVERAGE(E16:K16))
B17: Sommeil — routine (1/0) | E17: =IF('MON SUIVI QUOTIDIEN'!E83="Oui",1,IF('MON SUIVI QUOTIDIEN'!E83="Non",0,"")) | F17: =IF('MON SUIVI QUOTIDIEN'!F83="Oui",1,IF('MON SUIVI QUOTIDIEN'!F83="Non",0,"")) | G17: =IF('MON SUIVI QUOTIDIEN'!G83="Oui",1,IF('MON SUIVI QUOTIDIEN'!G83="Non",0,"")) | H17: =IF('MON SUIVI QUOTIDIEN'!H83="Oui",1,IF('MON SUIVI QUOTIDIEN'!H83="Non",0,"")) | I17: =IF('MON SUIVI QUOTIDIEN'!I83="Oui",1,IF('MON SUIVI QUOTIDIEN'!I83="Non",0,"")) | J17: =IF('MON SUIVI QUOTIDIEN'!J83="Oui",1,IF('MON SUIVI QUOTIDIEN'!J83="Non",0,"")) | K17: =IF('MON SUIVI QUOTIDIEN'!K83="Oui",1,IF('MON SUIVI QUOTIDIEN'!K83="Non",0,"")) | L17: =IF(COUNT(E17:K17)=0,"",AVERAGE(E17:K17))
B18: Sommeil — renseigné | E18: =IF(COUNTA('MON SUIVI QUOTIDIEN'!E80,'MON SUIVI QUOTIDIEN'!E81,'MON SUIVI QUOTIDIEN'!E83)>0,1,0) -> 0 | F18: =IF(COUNTA('MON SUIVI QUOTIDIEN'!F80,'MON SUIVI QUOTIDIEN'!F81,'MON SUIVI QUOTIDIEN'!F83)>0,1,0) -> 0 | G18: =IF(COUNTA('MON SUIVI QUOTIDIEN'!G80,'MON SUIVI QUOTIDIEN'!G81,'MON SUIVI QUOTIDIEN'!G83)>0,1,0) -> 0 | H18: =IF(COUNTA('MON SUIVI QUOTIDIEN'!H80,'MON SUIVI QUOTIDIEN'!H81,'MON SUIVI QUOTIDIEN'!H83)>0,1,0) -> 0 | I18: =IF(COUNTA('MON SUIVI QUOTIDIEN'!I80,'MON SUIVI QUOTIDIEN'!I81,'MON SUIVI QUOTIDIEN'!I83)>0,1,0) -> 0 | J18: =IF(COUNTA('MON SUIVI QUOTIDIEN'!J80,'MON SUIVI QUOTIDIEN'!J81,'MON SUIVI QUOTIDIEN'!J83)>0,1,0) -> 0 | K18: =IF(COUNTA('MON SUIVI QUOTIDIEN'!K80,'MON SUIVI QUOTIDIEN'!K81,'MON SUIVI QUOTIDIEN'!K83)>0,1,0) -> 0 | L18: =SUM(E18:K18) -> 0
B19: Sommeil — taux jour | E19: =IF(COUNT(E15:E17)=0,"",AVERAGE(E15:E17)) | F19: =IF(COUNT(F15:F17)=0,"",AVERAGE(F15:F17)) | G19: =IF(COUNT(G15:G17)=0,"",AVERAGE(G15:G17)) | H19: =IF(COUNT(H15:H17)=0,"",AVERAGE(H15:H17)) | I19: =IF(COUNT(I15:I17)=0,"",AVERAGE(I15:I17)) | J19: =IF(COUNT(J15:J17)=0,"",AVERAGE(J15:J17)) | K19: =IF(COUNT(K15:K17)=0,"",AVERAGE(K15:K17)) | L19: =IF(COUNT(L15:L17)=0,"",AVERAGE(L15:L17))
B21: Sport — minutes (ratio) | E21: =IF(OR('MON SUIVI QUOTIDIEN'!E88="",'MON SUIVI QUOTIDIEN'!$C$17<=0),"",MIN(1,'MON SUIVI QUOTIDIEN'!E88/'MON SUIVI QUOTIDIEN'!$C$17)) | F21: =IF(OR('MON SUIVI QUOTIDIEN'!F88="",'MON SUIVI QUOTIDIEN'!$C$17<=0),"",MIN(1,'MON SUIVI QUOTIDIEN'!F88/'MON SUIVI QUOTIDIEN'!$C$17)) | G21: =IF(OR('MON SUIVI QUOTIDIEN'!G88="",'MON SUIVI QUOTIDIEN'!$C$17<=0),"",MIN(1,'MON SUIVI QUOTIDIEN'!G88/'MON SUIVI QUOTIDIEN'!$C$17)) | H21: =IF(OR('MON SUIVI QUOTIDIEN'!H88="",'MON SUIVI QUOTIDIEN'!$C$17<=0),"",MIN(1,'MON SUIVI QUOTIDIEN'!H88/'MON SUIVI QUOTIDIEN'!$C$17)) | I21: =IF(OR('MON SUIVI QUOTIDIEN'!I88="",'MON SUIVI QUOTIDIEN'!$C$17<=0),"",MIN(1,'MON SUIVI QUOTIDIEN'!I88/'MON SUIVI QUOTIDIEN'!$C$17)) | J21: =IF(OR('MON SUIVI QUOTIDIEN'!J88="",'MON SUIVI QUOTIDIEN'!$C$17<=0),"",MIN(1,'MON SUIVI QUOTIDIEN'!J88/'MON SUIVI QUOTIDIEN'!$C$17)) | K21: =IF(OR('MON SUIVI QUOTIDIEN'!K88="",'MON SUIVI QUOTIDIEN'!$C$17<=0),"",MIN(1,'MON SUIVI QUOTIDIEN'!K88/'MON SUIVI QUOTIDIEN'!$C$17)) | L21: =IF(COUNT(E21:K21)=0,"",AVERAGE(E21:K21))
